<?xml version="1.0" encoding="UTF-8"?>
<!-- Generated by org.testng.reporters.JUnitReportReporter -->
<testsuite hostname="Dooby" failures="1" tests="4" name="com.dooby.testcases.CreateCustomerTest" time="3.170" errors="0" timestamp="2021-05-05T17:51:51 IST" skipped="0">
  <testcase classname="com.dooby.testcases.CreateCustomerTest" name="ValidateCreateCustomerAPIwithValidSecretKey" time="0.563"/>
  <system-out/>
  <testcase classname="com.dooby.testcases.CreateCustomerTest" name="ValidateCreateCustomerAPIwithValidSecretKey" time="0.760"/>
  <system-out/>
  <testcase classname="com.dooby.testcases.CreateCustomerTest" name="ValidateCreateCustomerAPIwithInValidSecretKey" time="1.294">
    <failure message="expected [200] but found [401]" type="java.lang.AssertionError">
      <![CDATA[java.lang.AssertionError: expected [200] but found [401]
at org.testng.Assert.fail(Assert.java:99)
at org.testng.Assert.failNotEquals(Assert.java:1037)
at org.testng.Assert.assertEqualsImpl(Assert.java:140)
at org.testng.Assert.assertEquals(Assert.java:122)
at org.testng.Assert.assertEquals(Assert.java:907)
at org.testng.Assert.assertEquals(Assert.java:917)
at com.dooby.testcases.CreateCustomerTest.ValidateCreateCustomerAPIwithInValidSecretKey(CreateCustomerTest.java:40)
at java.base/jdk.internal.reflect.NativeMethodAccessorImpl.invoke0(Native Method)
at java.base/jdk.internal.reflect.NativeMethodAccessorImpl.invoke(NativeMethodAccessorImpl.java:64)
at java.base/jdk.internal.reflect.DelegatingMethodAccessorImpl.invoke(DelegatingMethodAccessorImpl.java:43)
at java.base/java.lang.reflect.Method.invoke(Method.java:564)
at org.testng.internal.MethodInvocationHelper.invokeMethod(MethodInvocationHelper.java:132)
at org.testng.internal.TestInvoker.invokeMethod(TestInvoker.java:599)
at org.testng.internal.TestInvoker.invokeTestMethod(TestInvoker.java:174)
at org.testng.internal.TestMethodWithDataProviderMethodWorker.call(TestMethodWithDataProviderMethodWorker.java:77)
at org.testng.internal.TestMethodWithDataProviderMethodWorker.call(TestMethodWithDataProviderMethodWorker.java:15)
at java.base/java.util.concurrent.FutureTask.run(FutureTask.java:264)
at java.base/java.util.concurrent.Executors$RunnableAdapter.call(Executors.java:515)
at java.base/java.util.concurrent.FutureTask.run(FutureTask.java:264)
at java.base/java.util.concurrent.ThreadPoolExecutor.runWorker(ThreadPoolExecutor.java:1130)
at java.base/java.util.concurrent.ThreadPoolExecutor$Worker.run(ThreadPoolExecutor.java:630)
at java.base/java.lang.Thread.run(Thread.java:832)
]]>
    </failure>
  </testcase> <!-- ValidateCreateCustomerAPIwithInValidSecretKey -->
  <system-out/>
  <testcase classname="com.dooby.testcases.CreateCustomerTest" name="ValidateCreateCustomerAPIwithValidSecretKey" time="0.553"/>
  <system-out/>
</testsuite> <!-- com.dooby.testcases.CreateCustomerTest -->
